Workbook
Name tax_rate: #REF!

Sheet Income Statement
A1: Apex Solutions - Income Statement | C1: Historicals | F1: Forecasts
A2: (All Data is in Millions $, Except Per Share Information) | C2: Actuals 1 | D2: Actuals 2 | E2: Actuals 3 | F2: Year 1 | G2: Year 2 | H2: Year 3 | I2: Year 4 | J2: Year 5
B5: Revenues
B6: Software | C6: 12000 | D6: 15000 | E6: 18500 | F6: =E6*(1+F35) -> 22200 | G6: =F6*(1+G35) -> 26640 | H6: =G6*(1+H35) -> 31968 | I6: =H6*(1+I35) -> 38361.6 | J6: =I6*(1+J35) -> 46033.92
B7: Hardware | C7: 8500 | D7: 10200 | E7: 12300 | F7: =E7*(1+F36) -> 14514 | G7: =F7*(1+G36) -> 17126.52 | H7: =G7*(1+H36) -> 20209.294 | I7: =H7*(1+I36) -> 23846.966 | J7: =I7*(1+J36) -> 28139.42
B8: IT Services | C8: 5000 | D8: 6500 | E8: 8000 | F8: =E8*(1+F37) -> 9280 | G8: =F8*(1+G37) -> 10764.8 | H8: =G8*(1+H37) -> 12487.168 | I8: =H8*(1+I37) -> 14485.115 | J8: =I8*(1+J37) -> 16802.733
B9: Total Revenues | C9: =SUM(C6:C8) -> 25500 | D9: =SUM(D6:D8) -> 31700 | E9: =SUM(E6:E8) -> 38800 | F9: =SUM(F6:F8) -> 45994 | G9: =SUM(G6:G8) -> 54531.32 | H9: =SUM(H6:H8) -> 64664.462 | I9: =SUM(I6:I8) -> 76693.681 | J9: =SUM(J6:J8) -> 90976.074
B10: Cost of Sales
B11: Software | C11: 6000 | D11: 7500 | E11: 9200 | F11: =F41 -> 11100 | G11: =G41 -> 13320 | H11: =H41 -> 15984 | I11: =I41 -> 19180.8 | J11: =J41 -> 23016.96
B12: Hardware | C12: 4000 | D12: 4800 | E12: 5900 | F12: =F48 -> 6966.72 | G12: =G48 -> 8220.7296 | H12: =H48 -> 9700.4609 | I12: =I48 -> 11446.544 | J12: =J48 -> 13506.922
B13: IT Services | C13: 2500 | D13: 3250 | E13: 4000 | F13: =F55 -> 4640 | G13: =G55 -> 5382.4 | H13: =H55 -> 6243.584 | I13: =I55 -> 7242.5574 | J13: =J55 -> 8401.3666
B14: Total Operating Costs | C14: =SUM(C11:C13) -> 12500 | D14: =SUM(D11:D13) -> 15550 | E14: =SUM(E11:E13) -> 19100 | F14: =SUM(F11:F13) -> 22706.72 | G14: =SUM(G11:G13) -> 26923.13 | H14: =SUM(H11:H13) -> 31928.045 | I14: =SUM(I11:I13) -> 37869.901 | J14: =SUM(J11:J13) -> 44925.248
B16: Gross Margin | C16: =C9-C14 -> 13000 | D16: =D9-D14 -> 16150 | E16: =E9-E14 -> 19700 | F16: =F9-F14 -> 23287.28 | G16: =G9-G14 -> 27608.19 | H16: =H9-H14 -> 32736.417 | I16: =I9-I14 -> 38823.78 | J16: =J9-J14 -> 46050.825
B17: SG&A Expense | C17: 4000 | D17: 5000 | E17: 6000 | F17: =F9*F60 -> 6899.1 | G17: =G9*G60 -> 8179.698 | H17: =H9*H60 -> 9699.6692 | I17: =I9*I60 -> 11504.052 | J17: =J9*J60 -> 13646.411
B18: EBITDA | C18: =C16-C17 -> 9000 | D18: =D16-D17 -> 11150 | E18: =E16-E17 -> 13700 | F18: =F16-F17 -> 16388.18 | G18: =G16-G17 -> 19428.492 | H18: =H16-H17 -> 23036.747 | I18: =I16-I17 -> 27319.728 | J18: =J16-J17 -> 32404.414
B20: Depreciation | C20: 1200 | D20: 1400 | E20: 1700 | F20: ='Dep Capex'!F12 -> 2069.73 | G20: ='Dep Capex'!G12 -> 2453.9094 | H20: ='Dep Capex'!H12 -> 2909.9008 | I20: ='Dep Capex'!I12 -> 3451.2157 | J20: ='Dep Capex'!J12 -> 4093.9233
B21: Amortization | C21: 0 | D21: 0 | E21: 0 | F21: 0 | G21: 0 | H21: 0 | I21: 0 | J21: 0
B22: EBIT | C22: =C18-C20-C21 -> 7800 | D22: =D18-D20-D21 -> 9750 | E22: =E18-E20-E21 -> 12000 | F22: =F18-F20-F21 -> 14318.45 | G22: =G18-G20-G21 -> 16974.583 | H22: =H18-H20-H21 -> 20126.847 | I22: =I18-I20-I21 -> 23868.512 | J22: =J18-J20-J21 -> 28310.491
B24: Interest Expense | C24: 2200 | D24: 2050 | E24: 1800 | F24: =Debt!F15 -> 2223 | G24: =Debt!G15 -> 2133 | H24: =Debt!H15 -> 2043 | I24: =Debt!I15 -> 1953 | J24: =Debt!J15 -> 1863
B25: Interest Income | C25: 100 | D25: 150 | E25: 200 | F25: =Debt!F20 -> 42 | G25: =Debt!G20 -> 36.125528 | H25: =Debt!H20 -> 55.676106 | I25: =Debt!I20 -> 114.94502 | J25: =Debt!J20 -> 260.21186
B26: Net Interest Expense | C26: =C24-C25 -> 2100 | D26: =D24-D25 -> 1900 | E26: =E24-E25 -> 1600 | F26: =F24-F25 -> 2181 | G26: =G24-G25 -> 2096.8745 | H26: =H24-H25 -> 1987.3239 | I26: =I24-I25 -> 1838.055 | J26: =J24-J25 -> 1602.7881
B28: EBT | C28: =C22-C26 -> 5700 | D28: =D22-D26 -> 7850 | E28: =E22-E26 -> 10400 | F28: =F22-F26 -> 12137.45 | G28: =G22-G26 -> 14877.709 | H28: =H22-H26 -> 18139.523 | I28: =I22-I26 -> 22030.457 | J28: =J22-J26 -> 26707.703
B29: Tax | C29: 1325 | D29: 1837.5 | E29: 2450 | F29: =F28*F62 -> 2840.1633 | G29: =G28*G62 -> 3481.3838 | H29: =H28*H62 -> 4244.6483 | I29: =I28*I62 -> 5155.127 | J29: =J28*J62 -> 6249.6024
B30: Net income | C30: =C28-C29 -> 4375 | D30: =D28-D29 -> 6012.5 | E30: =E28-E29 -> 7950 | F30: =F28-F29 -> 9297.2867 | G30: =G28-G29 -> 11396.325 | H30: =H28-H29 -> 13894.874 | I30: =I28-I29 -> 16875.33 | J30: =J28-J29 -> 20458.1
B33: Drivers
B34: Revenues
B35: Software | D35: =D6/C6-1 -> 0.25 | E35: =E6/D6-1 -> 0.23333333 | F35: 0.2 | G35: 0.2 | H35: 0.2 | I35: 0.2 | J35: 0.2
B36: Hardware | D36: =D7/C7-1 -> 0.2 | E36: =E7/D7-1 -> 0.20588235 | F36: 0.18 | G36: 0.18 | H36: 0.18 | I36: 0.18 | J36: 0.18
B37: IT Services | D37: =D8/C8-1 -> 0.3 | E37: =E8/D8-1 -> 0.23076923 | F37: 0.16 | G37: 0.16 | H37: 0.16 | I37: 0.16 | J37: 0.16
B39: Software
B40: Software Revenue | C40: =C6 -> 12000 | D40: =D6 -> 15000 | E40: =E6 -> 18500 | F40: =F6 -> 22200 | G40: =G6 -> 26640 | H40: =H6 -> 31968 | I40: =I6 -> 38361.6 | J40: =J6 -> 46033.92
B41: Software Cost of Sales | C41: =C11 -> 6000 | D41: =D11 -> 7500 | E41: =E11 -> 9200 | F41: =F40*F42 -> 11100 | G41: =G40*G42 -> 13320 | H41: =H40*H42 -> 15984 | I41: =I40*I42 -> 19180.8 | J41: =J40*J42 -> 23016.96
B42: Cost of Sales (%) | C42: =C41/C40 -> 0.5 | D42: =D41/D40 -> 0.5 | E42: =E41/E40 -> 0.4972973 | F42: 0.5 | G42: 0.5 | H42: 0.5 | I42: 0.5 | J42: 0.5
B43: Margin ($ million) | C43: =C40-C41 -> 6000 | D43: =D40-D41 -> 7500 | E43: =E40-E41 -> 9300 | F43: =F40-F41 -> 11100 | G43: =G40-G41 -> 13320 | H43: =H40-H41 -> 15984 | I43: =I40-I41 -> 19180.8 | J43: =J40-J41 -> 23016.96
B44: Margin (%) | C44: =C43/C40 -> 0.5 | D44: =D43/D40 -> 0.5 | E44: =E43/E40 -> 0.5027027 | F44: =F43/F40 -> 0.5 | G44: =G43/G40 -> 0.5 | H44: =H43/H40 -> 0.5 | I44: =I43/I40 -> 0.5 | J44: =J43/J40 -> 0.5
B46: Hardware
B47: Hardware Revenue | C47: =C7 -> 8500 | D47: =D7 -> 10200 | E47: =E7 -> 12300 | F47: =F7 -> 14514 | G47: =G7 -> 17126.52 | H47: =H7 -> 20209.294 | I47: =I7 -> 23846.966 | J47: =J7 -> 28139.42
B48: Hardware Cost of Sales | C48: =C12 -> 4000 | D48: =D12 -> 4800 | E48: =E12 -> 5900 | F48: =F47*F49 -> 6966.72 | G48: =G47*G49 -> 8220.7296 | H48: =H47*H49 -> 9700.4609 | I48: =I47*I49 -> 11446.544 | J48: =J47*J49 -> 13506.922
B49: Cost of Sales (%) | C49: =C48/C47 -> 0.47058824 | D49: =D48/D47 -> 0.47058824 | E49: =E48/E47 -> 0.4796748 | F49: 0.48 | G49: 0.48 | H49: 0.48 | I49: 0.48 | J49: 0.48
B50: Margin ($ million) | C50: =C47-C48 -> 4500 | D50: =D47-D48 -> 5400 | E50: =E47-E48 -> 6400 | F50: =F47-F48 -> 7547.28 | G50: =G47-G48 -> 8905.7904 | H50: =H47-H48 -> 10508.833 | I50: =I47-I48 -> 12400.423 | J50: =J47-J48 -> 14632.499
...

Sheet Balance Sheet
A1: Apex Solutions - Balance Sheet | C1: Historicals | F1: Forecasts
A2: (All Data is in Millions $, Except Per Share Information) | C2: Actuals 1 | D2: Actuals 2 | E2: Actuals 3 | F2: Year 1 | G2: Year 2 | H2: Year 3 | I2: Year 4 | J2: Year 5
B5: Assets
B6: Current Assets
B7: Cash and Equivalents | C7: 1200 | D7: 1300 | E7: 1400 | F7: ='Cash Flow'!F27 -> 1204.1843 | G7: ='Cash Flow'!G27 -> 1855.8702 | H7: ='Cash Flow'!H27 -> 3831.5007 | I7: ='Cash Flow'!I27 -> 8673.7287 | J7: ='Cash Flow'!J27 -> 16057.031
B8: Accounts Receivables | C8: 1440 | D8: 1700 | E8: 1960 | F8: ='Working Capital'!F7 -> 2394.2082 | G8: ='Working Capital'!G7 -> 2838.6167 | H8: ='Working Capital'!H7 -> 3366.0953 | I8: ='Working Capital'!I7 -> 3992.2738 | J8: ='Working Capital'!J7 -> 4735.7408
B9: Inventory | C9: =2800+300 -> 3100 | D9: =3200+360 -> 3560 | E9: =3600+400 -> 4000 | F9: ='Working Capital'!F8 -> 4354.7134 | G9: ='Working Capital'!G8 -> 5163.3399 | H9: ='Working Capital'!H8 -> 6123.1867 | I9: ='Working Capital'!I8 -> 7262.7208 | J9: ='Working Capital'!J8 -> 8615.8011
B10: Total Current Assets | C10: =SUM(C7:C9) -> 5740 | D10: =SUM(D7:D9) -> 6560 | E10: =SUM(E7:E9) -> 7360 | F10: =SUM(F7:F9) -> 7953.1059 | G10: =SUM(G7:G9) -> 9857.8268 | H10: =SUM(H7:H9) -> 13320.783 | I10: =SUM(I7:I9) -> 19928.723 | J10: =SUM(J7:J9) -> 29408.573
B12: Fixed Assets
B13: Net PPE | C13: 24800 | D13: 28100 | E13: 31400 | F13: ='Dep Capex'!F13 -> 39330.27 | G13: ='Dep Capex'!G13 -> 48376.361 | H13: ='Dep Capex'!H13 -> 58466.46 | I13: ='Dep Capex'!I13 -> 68515.244 | J13: ='Dep Capex'!J13 -> 79421.321
B15: Other Assets
B16: Goodwill | C16: 1800 | D16: 2100 | E16: 2400 | F16: =E16 -> 2400 | G16: =F16 -> 2400 | H16: =G16 -> 2400 | I16: =H16 -> 2400 | J16: =I16 -> 2400
B17: Intangible Assets | C17: 0 | D17: 0 | E17: 0 | F17: 0 | G17: 0 | H17: 0 | I17: 0 | J17: 0
B18: Total Other Assets | C18: =SUM(C16:C17) -> 1800 | D18: =SUM(D16:D17) -> 2100 | E18: =SUM(E16:E17) -> 2400 | F18: =SUM(F16:F17) -> 2400 | G18: =SUM(G16:G17) -> 2400 | H18: =SUM(H16:H17) -> 2400 | I18: =SUM(I16:I17) -> 2400 | J18: =SUM(J16:J17) -> 2400
B20: Total Assets | C20: =C10+C13+C18 -> 32340 | D20: =D10+D13+D18 -> 36760 | E20: =E10+E13+E18 -> 41160 | F20: =F10+F13+F18 -> 49683.376 | G20: =G10+G13+G18 -> 60634.187 | H20: =H10+H13+H18 -> 74187.242 | I20: =I10+I13+I18 -> 90843.967 | J20: =J10+J13+J18 -> 111229.89
B22: Liabilities and Shareholders Equity
B23: Current Liabilities
B24: Accounts Payable | C24: =1800+400 -> 2200 | D24: =2000+480 -> 2480 | E24: =2200+560 -> 2760 | F24: ='Working Capital'!F9 -> 2986.0892 | G24: ='Working Capital'!G9 -> 3540.5759 | H24: ='Working Capital'!H9 -> 4198.7566 | I24: ='Working Capital'!I9 -> 4980.1514 | J24: ='Working Capital'!J9 -> 5907.9779
B25: Total Current Liabilities | C25: =SUM(C24:C24) -> 2200 | D25: =SUM(D24:D24) -> 2480 | E25: =SUM(E24:E24) -> 2760 | F25: =SUM(F24:F24) -> 2986.0892 | G25: =SUM(G24:G24) -> 3540.5759 | H25: =SUM(H24:H24) -> 4198.7566 | I25: =SUM(I24:I24) -> 4980.1514 | J25: =SUM(J24:J24) -> 5907.9779
B27: Term Loan | C27: 21000 | D27: 23100 | E27: 25200 | F27: =Debt!F10 -> 24200 | G27: =Debt!G10 -> 23200 | H27: =Debt!H10 -> 22200 | I27: =Debt!I10 -> 21200 | J27: =Debt!J10 -> 20200
B28: Total Debt | C28: =SUM(C27:C27) -> 21000 | D28: =SUM(D27:D27) -> 23100 | E28: =SUM(E27:E27) -> 25200 | F28: =SUM(F27:F27) -> 24200 | G28: =SUM(G27:G27) -> 23200 | H28: =SUM(H27:H27) -> 22200 | I28: =SUM(I27:I27) -> 21200 | J28: =SUM(J27:J27) -> 20200
B30: Common Stock | C30: 2000 | D30: 2200 | E30: 2400 | F30: =E30 -> 2400 | G30: =F30 -> 2400 | H30: =G30 -> 2400 | I30: =H30 -> 2400 | J30: =I30 -> 2400
B31: Treasury Stock | C31: -1000 | D31: -1100 | E31: -1200 | F31: =E31 -> -1200 | G31: =F31 -> -1200 | H31: =G31 -> -1200 | I31: =H31 -> -1200 | J31: =I31 -> -1200
B32: Retained Earnings | C32: 8140 | D32: 10080 | E32: 12000 | F32: =E32+'Income Statement'!F30 -> 21297.287 | G32: =F32+'Income Statement'!G30 -> 32693.611 | H32: =G32+'Income Statement'!H30 -> 46588.486 | I32: =H32+'Income Statement'!I30 -> 63463.816 | J32: =I32+'Income Statement'!J30 -> 83921.916
B33: Shareholders' Equity (Deficit) | C33: =SUM(C30:C32) -> 9140 | D33: =SUM(D30:D32) -> 11180 | E33: =SUM(E30:E32) -> 13200 | F33: =SUM(F30:F32) -> 22497.287 | G33: =SUM(G30:G32) -> 33893.611 | H33: =SUM(H30:H32) -> 47788.486 | I33: =SUM(I30:I32) -> 64663.816 | J33: =SUM(J30:J32) -> 85121.916
B35: Total Liabilities and Shareholders' Equity (Deficit) | C35: =C33+C25+C28 -> 32340 | D35: =D33+D25+D28 -> 36760 | E35: =E33+E25+E28 -> 41160 | F35: =F33+F25+F28 -> 49683.376 | G35: =G33+G25+G28 -> 60634.187 | H35: =H33+H25+H28 -> 74187.242 | I35: =I33+I25+I28 -> 90843.967 | J35: =J33+J25+J28 -> 111229.89
B37: Check | C37: =C20-C35 -> 0 | D37: =D20-D35 -> 0 | E37: =E20-E35 -> 0 | F37: =F20-F35 -> 0 | G37: =G20-G35 -> 0 | H37: =H20-H35 -> 0 | I37: =I20-I35 -> 0 | J37: =J20-J35 -> 0
B39: Liquidity Ratio
B40: Current Ratio (Current Assets / Current Liablities) | C40: =C10/C25 -> 2.6090909 | D40: =D10/D25 -> 2.6451613 | E40: =E10/E25 -> 2.6666667 | F40: =F10/F25 -> 2.6633852 | G40: =G10/G25 -> 2.7842438 | H40: =H10/H25 -> 3.1725541 | I40: =I10/I25 -> 4.00163 | J40: =J10/J25 -> 4.9777731
B41: Quick Ratio | C41: =(C7+C8)/C25 -> 1.2 | D41: =(D7+D8)/D25 -> 1.2096774 | E41: =(E7+E8)/E25 -> 1.2173913 | F41: =(F7+F8)/F25 -> 1.2050519 | G41: =(G7+G8)/G25 -> 1.3259105 | H41: =(H7+H8)/H25 -> 1.7142208 | I41: =(I7+I8)/I25 -> 2.5432967 | J41: =(J7+J8)/J25 -> 3.5194398
B42: Cash Ratio | C42: =C7/C25 -> 0.54545455 | D42: =D7/D25 -> 0.52419355 | E42: =E7/E25 -> 0.50724638 | F42: =F7/F25 -> 0.40326466 | G42: =G7/G25 -> 0.52417184 | H42: =H7/H25 -> 0.91253222 | I42: =I7/I25 -> 1.7416596 | J42: =J7/J25 -> 2.7178557
B44: Leverage Ratio
B45: Debt to Equity Ratio | C45: =C28/C33 -> 2.297593 | D45: =D28/D33 -> 2.0661896 | E45: =E28/E33 -> 1.9090909 | F45: =F28/F33 -> 1.0756853 | G45: =G28/G33 -> 0.68449478 | H45: =H28/H33 -> 0.46454705 | I45: =I28/I33 -> 0.3278495 | J45: =J28/J33 -> 0.23730669
B47: ROE (Net Income / Shareholders Equity) | C47: ='Income Statement'!C30/'Balance Sheet'!C33 -> 0.47866521 | D47: ='Income Statement'!D30/'Balance Sheet'!D33 -> 0.5377907 | E47: ='Income Statement'!E30/'Balance Sheet'!E33 -> 0.60227273 | F47: ='Income Statement'!F30/'Balance Sheet'!F33 -> 0.41326258 | G47: ='Income Statement'!G30/'Balance Sheet'!G33 -> 0.33623814 | H47: ='Income Statement'!H30/'Balance Sheet'!H33 -> 0.29075779 | I47: ='Income Statement'!I30/'Balance Sheet'!I33 -> 0.26097022 | J47: ='Income Statement'!J30/'Balance Sheet'!J33 -> 0.24033881
B49: *We are assuming that management has made a decision of not buying back stock for now.
B50: *Hence, we assume that Treasury Stock remains the same in the years forecasted
B51: *Also, since there is not Follow on IPO we are assuming that the common stock forecasted for the future also remains the same
B52: *We are assuming that No Dividends were given and hence all of the net income was invested back into the company
B53: *Hence, Retained Earnings forecasted is equal to the sum of the previous year Retained Earning and Net Income

Sheet Cash Flow
A1: Apex Solutions - Cash Flow | C1: Historicals | F1: Forecasts
A2: (All Data is in Millions $, Except Per Share Information) | C2: Actuals 1 | D2: Actuals 2 | E2: Actuals 3 | F2: Year 1 | G2: Year 2 | H2: Year 3 | I2: Year 4 | J2: Year 5
B6: Operating Activities
B7: Net Income | F7: ='Income Statement'!F30 -> 9297.2867 | G7: ='Income Statement'!G30 -> 11396.325 | H7: ='Income Statement'!H30 -> 13894.874 | I7: ='Income Statement'!I30 -> 16875.33 | J7: ='Income Statement'!J30 -> 20458.1
B8: Add Depreciation | F8: ='Dep Capex'!F12 -> 2069.73 | G8: ='Dep Capex'!G12 -> 2453.9094 | H8: ='Dep Capex'!H12 -> 2909.9008 | I8: ='Dep Capex'!I12 -> 3451.2157 | J8: ='Dep Capex'!J12 -> 4093.9233
B9: Add Amortization | F9: ='Income Statement'!F21 -> 0 | G9: ='Income Statement'!G21 -> 0 | H9: ='Income Statement'!H21 -> 0 | I9: ='Income Statement'!I21 -> 0 | J9: ='Income Statement'!J21 -> 0
B10: Change in Working Capital
B11: Change in Receivable | F11: ='Working Capital'!E7-'Working Capital'!F7 -> -434.20822 | G11: ='Working Capital'!F7-'Working Capital'!G7 -> -444.40844 | H11: ='Working Capital'!G7-'Working Capital'!H7 -> -527.4786 | I11: ='Working Capital'!H7-'Working Capital'!I7 -> -626.17856 | J11: ='Working Capital'!I7-'Working Capital'!J7 -> -743.467
B12: Change in Inventory | F12: ='Working Capital'!E8-'Working Capital'!F8 -> -354.71342 | G12: ='Working Capital'!F8-'Working Capital'!G8 -> -808.6265 | H12: ='Working Capital'!G8-'Working Capital'!H8 -> -959.84678 | I12: ='Working Capital'!H8-'Working Capital'!I8 -> -1139.5341 | J12: ='Working Capital'!I8-'Working Capital'!J8 -> -1353.0803
B13: Change in Accounts Payable | F13: ='Working Capital'!F9-'Working Capital'!E9 -> 226.08921 | G13: ='Working Capital'!G9-'Working Capital'!F9 -> 554.48674 | H13: ='Working Capital'!H9-'Working Capital'!G9 -> 658.18065 | I13: ='Working Capital'!I9-'Working Capital'!H9 -> 781.39482 | J13: ='Working Capital'!J9-'Working Capital'!I9 -> 927.82647
B14: Cash Flow from Operating Activities | F14: =SUM(F7:F13) -> 10804.184 | G14: =SUM(G7:G13) -> 13151.686 | H14: =SUM(H7:H13) -> 15975.63 | I14: =SUM(I7:I13) -> 19342.228 | J14: =SUM(J7:J13) -> 23383.303
B16: Investment Activities
B17: Capital Expenditures | F17: =-'Dep Capex'!F11 -> -10000 | G17: =-'Dep Capex'!G11 -> -11500 | H17: =-'Dep Capex'!H11 -> -13000 | I17: =-'Dep Capex'!I11 -> -13500 | J17: =-'Dep Capex'!J11 -> -15000
B18: Additions to Intangibles | F18: ='Balance Sheet'!F17-'Balance Sheet'!E17 -> 0 | G18: ='Balance Sheet'!G17-'Balance Sheet'!F17 -> 0 | H18: ='Balance Sheet'!H17-'Balance Sheet'!G17 -> 0 | I18: ='Balance Sheet'!I17-'Balance Sheet'!H17 -> 0 | J18: ='Balance Sheet'!J17-'Balance Sheet'!I17 -> 0
B19: Cash Flow from Investing Activities | F19: =SUM(F17:F18) -> -10000 | G19: =SUM(G17:G18) -> -11500 | H19: =SUM(H17:H18) -> -13000 | I19: =SUM(I17:I18) -> -13500 | J19: =SUM(J17:J18) -> -15000
B21: Financing Activities
B22: Proceeds from/ (repayment of) Term Loan | F22: =Debt!F8+Debt!F9 -> -1000 | G22: =Debt!G8+Debt!G9 -> -1000 | H22: =Debt!H8+Debt!H9 -> -1000 | I22: =Debt!I8+Debt!I9 -> -1000 | J22: =Debt!J8+Debt!J9 -> -1000
B23: Cash Flow from Financing Activities | F23: =F22 -> -1000 | G23: =G22 -> -1000 | H23: =H22 -> -1000 | I23: =I22 -> -1000 | J23: =J22 -> -1000
B25: Net Change in Cash | F25: =SUM(F14,F19,F23) -> -195.81574 | G25: =SUM(G14,G19,G23) -> 651.68594 | H25: =SUM(H14,H19,H23) -> 1975.6305 | I25: =SUM(I14,I19,I23) -> 4842.228 | J25: =SUM(J14,J19,J23) -> 7383.3028
B26: Beginning Cash Balance | F26: =E27 -> 1400 | G26: =F27 -> 1204.1843 | H26: =G27 -> 1855.8702 | I26: =H27 -> 3831.5007 | J26: =I27 -> 8673.7287
B27: Ending Cash Balance | E27: ='Balance Sheet'!E7 -> 1400 | F27: =SUM(F25:F26) -> 1204.1843 | G27: =SUM(G25:G26) -> 1855.8702 | H27: =SUM(H25:H26) -> 3831.5007 | I27: =SUM(I25:I26) -> 8673.7287 | J27: =SUM(J25:J26) -> 16057.031

Sheet Dep Capex
A1: Apex Solutions - Depreciation Capex | C1: Historicals | F1: Forecasts
A2: (All Data is in Millions $, Except Per Share Information) | C2: Actuals 1 | D2: Actuals 2 | E2: Actuals 3 | F2: Year 1 | G2: Year 2 | H2: Year 3 | I2: Year 4 | J2: Year 5
B5: Revenue | C5: ='Income Statement'!C9 -> 25500 | D5: ='Income Statement'!D9 -> 31700 | E5: ='Income Statement'!E9 -> 38800 | F5: ='Income Statement'!F9 -> 45994 | G5: ='Income Statement'!G9 -> 54531.32 | H5: ='Income Statement'!H9 -> 64664.462 | I5: ='Income Statement'!I9 -> 76693.681 | J5: ='Income Statement'!J9 -> 90976.074
B7: Depreciation | C7: ='Income Statement'!C20 -> 1200 | D7: ='Income Statement'!D20 -> 1400 | E7: ='Income Statement'!E20 -> 1700 | F7: =F5*F8 -> 2069.73 | G7: =G5*G8 -> 2453.9094 | H7: =H5*H8 -> 2909.9008 | I7: =I5*I8 -> 3451.2157 | J7: =J5*J8 -> 4093.9233
B8: Depreciation as % of Revenue | C8: =C7/C5 -> 0.047058824 | D8: =D7/D5 -> 0.044164038 | E8: =E7/E5 -> 0.043814433 | F8: 0.045 | G8: 0.045 | H8: 0.045 | I8: 0.045 | J8: 0.045
B10: Beginning PP&E | F10: =E13 -> 31400 | G10: =F13 -> 39330.27 | H10: =G13 -> 48376.361 | I10: =H13 -> 58466.46 | J10: =I13 -> 68515.244
B11: Capital Expenditure | F11: 10000 | G11: 11500 | H11: 13000 | I11: 13500 | J11: 15000
B12: Depreciation | F12: =F7 -> 2069.73 | G12: =G7 -> 2453.9094 | H12: =H7 -> 2909.9008 | I12: =I7 -> 3451.2157 | J12: =J7 -> 4093.9233
B13: Net PPE | E13: ='Balance Sheet'!E13 -> 31400 | F13: =F10+F11-F12 -> 39330.27 | G13: =G10+G11-G12 -> 48376.361 | H13: =H10+H11-H12 -> 58466.46 | I13: =I10+I11-I12 -> 68515.244 | J13: =J10+J11-J12 -> 79421.321

Sheet Working Capital
A1: Apex Solutions - Working Capital | C1: Historicals | F1: Forecasts
A2: (All Data is in Millions $, Except Per Share Information) | C2: Actuals 1 | D2: Actuals 2 | E2: Actuals 3 | F2: Year 1 | G2: Year 2 | H2: Year 3 | I2: Year 4 | J2: Year 5
B6: Working Capital Balances
B7: Accounts Receivables | C7: ='Balance Sheet'!C8 -> 1440 | D7: ='Balance Sheet'!D8 -> 1700 | E7: ='Balance Sheet'!E8 -> 1960 | F7: =F11/F15 -> 2394.2082 | G7: =G11/G15 -> 2838.6167 | H7: =H11/H15 -> 3366.0953 | I7: =I11/I15 -> 3992.2738 | J7: =J11/J15 -> 4735.7408
B8: Inventory | C8: ='Balance Sheet'!C9 -> 3100 | D8: ='Balance Sheet'!D9 -> 3560 | E8: ='Balance Sheet'!E9 -> 4000 | F8: =F12/F16 -> 4354.7134 | G8: =G12/G16 -> 5163.3399 | H8: =H12/H16 -> 6123.1867 | I8: =I12/I16 -> 7262.7208 | J8: =J12/J16 -> 8615.8011
B9: Accounts Payable | C9: ='Balance Sheet'!C24 -> 2200 | D9: ='Balance Sheet'!D24 -> 2480 | E9: ='Balance Sheet'!E24 -> 2760 | F9: =F12/F17 -> 2986.0892 | G9: =G12/G17 -> 3540.5759 | H9: =H12/H17 -> 4198.7566 | I9: =I12/I17 -> 4980.1514 | J9: =J12/J17 -> 5907.9779
B11: Total Revenues | C11: ='Income Statement'!C9 -> 25500 | D11: ='Income Statement'!D9 -> 31700 | E11: ='Income Statement'!E9 -> 38800 | F11: ='Income Statement'!F9 -> 45994 | G11: ='Income Statement'!G9 -> 54531.32 | H11: ='Income Statement'!H9 -> 64664.462 | I11: ='Income Statement'!I9 -> 76693.681 | J11: ='Income Statement'!J9 -> 90976.074
B12: Operating Costs | C12: ='Income Statement'!C14 -> 12500 | D12: ='Income Statement'!D14 -> 15550 | E12: ='Income Statement'!E14 -> 19100 | F12: ='Income Statement'!F14 -> 22706.72 | G12: ='Income Statement'!G14 -> 26923.13 | H12: ='Income Statement'!H14 -> 31928.045 | I12: ='Income Statement'!I14 -> 37869.901 | J12: ='Income Statement'!J14 -> 44925.248
B14: Turnover Ratios
B15: Receivables turnover = (Sales / Accounts Receivables) | C15: =C11/C7 -> 17.708333 | D15: =D11/D7 -> 18.647059 | E15: =E11/E7 -> 19.795918 | F15: =$L$16/F19 -> 19.210526 | G15: =$L$16/G19 -> 19.210526 | H15: =$L$16/H19 -> 19.210526 | I15: =$L$16/I19 -> 19.210526 | J15: =$L$16/J19 -> 19.210526 | L15: days
B16: Inventory turnover (COGS / Inventory) | C16: =C12/C8 -> 4.0322581 | D16: =D12/D8 -> 4.3679775 | E16: =E12/E8 -> 4.775 | F16: =$L$16/F20 -> 5.2142857 | G16: =$L$16/G20 -> 5.2142857 | H16: =$L$16/H20 -> 5.2142857 | I16: =$L$16/I20 -> 5.2142857 | J16: =$L$16/J20 -> 5.2142857 | L16: 365
B17: Payables turnover (COGS / Payables) | C17: =C12/C9 -> 5.6818182 | D17: =D12/D9 -> 6.2701613 | E17: =E12/E9 -> 6.9202899 | F17: =$L$16/F21 -> 7.6041667 | G17: =$L$16/G21 -> 7.6041667 | H17: =$L$16/H21 -> 7.6041667 | I17: =$L$16/I21 -> 7.6041667 | J17: =$L$16/J21 -> 7.6041667
B19: Receivables collection period (365/receivables turnover) | C19: =$L$16/C15 -> 20.611765 | D19: =$L$16/D15 -> 19.574132 | E19: =$L$16/E15 -> 18.438144 | F19: 19 | G19: 19 | H19: 19 | I19: 19 | J19: 19
B20: Inventory processing period (365/inventory turnover) | C20: =$L$16/C16 -> 90.52 | D20: =$L$16/D16 -> 83.562701 | E20: =$L$16/E16 -> 76.439791 | F20: 70 | G20: 70 | H20: 70 | I20: 70 | J20: 70
B21: Payment period (365/payables turnover) | C21: =$L$16/C17 -> 64.24 | D21: =$L$16/D17 -> 58.212219 | E21: =$L$16/E17 -> 52.743455 | F21: 48 | G21: 48 | H21: 48 | I21: 48 | J21: 48
B22: Cash Collection Cycle | C22: =C19+C20-C21 -> 46.891765 | D22: =D19+D20-D21 -> 44.924615 | E22: =E19+E20-E21 -> 42.134479 | F22: =F19+F20-F21 -> 41 | G22: =G19+G20-G21 -> 41 | H22: =H19+H20-H21 -> 41 | I22: =I19+I20-I21 -> 41 | J22: =J19+J20-J21 -> 41

Sheet Debt
A1: Apex Solutions - Debt and Interest | C1: Historicals | F1: Forecasts
A2: (All Data is in Millions $, Except Per Share Information) | C2: Actuals 1 | D2: Actuals 2 | E2: Actuals 3 | F2: Year 1 | G2: Year 2 | H2: Year 3 | I2: Year 4 | J2: Year 5
B6: Term Loan
B7: Beginning Balance | F7: =E10 -> 25200 | G7: =F10 -> 24200 | H7: =G10 -> 23200 | I7: =H10 -> 22200 | J7: =I10 -> 21200
B8: Issuance | F8: 1000 | G8: 1000 | H8: 1000 | I8: 1000 | J8: 1000
B9: (Repayment/ Amortization) | F9: -2000 | G9: -2000 | H9: -2000 | I9: -2000 | J9: -2000
B10: Ending Balance | E10: ='Balance Sheet'!E27 -> 25200 | F10: =SUM(F7:F9) -> 24200 | G10: =SUM(G7:G9) -> 23200 | H10: =SUM(H7:H9) -> 22200 | I10: =SUM(I7:I9) -> 21200 | J10: =SUM(J7:J9) -> 20200
B12: Interest Expense Calculation
B13: Average Oustanding | F13: =AVERAGE(E10:F10) -> 24700 | G13: =AVERAGE(F10:G10) -> 23700 | H13: =AVERAGE(G10:H10) -> 22700 | I13: =AVERAGE(H10:I10) -> 21700 | J13: =AVERAGE(I10:J10) -> 20700
B14: Interest Rate | F14: 0.09 | G14: 0.09 | H14: 0.09 | I14: 0.09 | J14: 0.09
B15: Interest Expense | F15: =F13*F14 -> 2223 | G15: =G13*G14 -> 2133 | H15: =H13*H14 -> 2043 | I15: =I13*I14 -> 1953 | J15: =J13*J14 -> 1863
B17: Interest Income Calculation
B18: Cash & Cash Equivalents | F18: ='Cash Flow'!F26 -> 1400 | G18: ='Cash Flow'!G26 -> 1204.1843 | H18: ='Cash Flow'!H26 -> 1855.8702 | I18: ='Cash Flow'!I26 -> 3831.5007 | J18: ='Cash Flow'!J26 -> 8673.7287
B19: Effective Cash Interest Rate: | F19: 0.03 | G19: 0.03 | H19: 0.03 | I19: 0.03 | J19: 0.03
B20: Interest Income | F20: =F18*F19 -> 42 | G20: =G18*G19 -> 36.125528 | H20: =H18*H19 -> 55.676106 | I20: =I18*I19 -> 114.94502 | J20: =J18*J19 -> 260.21186
B23: *For Cash & Cash Equivalents we are using Beginning Cash Balance
B24: *We are assuming the year's interest income is based on the cash available at the start of the year

Sheet Dashboard
B1: APEX SOLUTIONS INC | H1: FINANCIAL STATEMENT ANALYSIS DASHBOARD
B4: Revenue | F4: Net Income | J4: Cash Balance | N4: Total Debt | R4: Free Cash Flow | V4: EBITDA Margin
B7: ='Income Statement'!J9 -> 90976.074 | F7: ='Income Statement'!J30 -> 20458.1 | J7: ='Cash Flow'!J27 -> 16057.031 | N7: ='Balance Sheet'!J28 -> 20200 | R7: ='Cash Flow'!J14-'Dep Capex'!J11 -> 8383.3028 | V7: ='Income Statement'!J18/'Income Statement'!J9 -> 0.35618611

Sheet Tables
B3: Year | C3: Software | E3: Hardware | F3: IT Services | H3: Year | I3: Net Income | K3: Year | L3: Total Operating Costs | O3: Year | P3: Revenue Growth | R3: Year | S3: Total Debt | U3: Year | V3: Total Assets
B4: Year 1 | C4: ='Income Statement'!F6 -> 22200 | E4: ='Income Statement'!F7 -> 14514 | F4: ='Income Statement'!F8 -> 9280 | H4: Year 1 | I4: ='Income Statement'!F30 -> 9297.2867 | K4: Year 1 | L4: ='Income Statement'!F14 -> 22706.72 | O4: Year 1 | P4: ='Income Statement'!F9 -> 45994 | R4: Year 1 | S4: ='Balance Sheet'!F28 -> 24200 | U4: Year 1 | V4: ='Balance Sheet'!F20 -> 49683.376
B5: Year 2 | C5: ='Income Statement'!G6 -> 26640 | E5: ='Income Statement'!G7 -> 17126.52 | F5: ='Income Statement'!G8 -> 10764.8 | H5: Year 2 | I5: ='Income Statement'!G30 -> 11396.325 | K5: Year 2 | L5: ='Income Statement'!G14 -> 26923.13 | O5: Year 2 | P5: ='Income Statement'!G9 -> 54531.32 | R5: Year 2 | S5: ='Balance Sheet'!G28 -> 23200 | U5: Year 2 | V5: ='Balance Sheet'!G20 -> 60634.187
B6: Year 3 | C6: ='Income Statement'!H6 -> 31968 | E6: ='Income Statement'!H7 -> 20209.294 | F6: ='Income Statement'!H8 -> 12487.168 | H6: Year 3 | I6: ='Income Statement'!H30 -> 13894.874 | K6: Year 3 | L6: ='Income Statement'!H14 -> 31928.045 | O6: Year 3 | P6: ='Income Statement'!H9 -> 64664.462 | R6: Year 3 | S6: ='Balance Sheet'!H28 -> 22200 | U6: Year 3 | V6: ='Balance Sheet'!H20 -> 74187.242
B7: Year 4 | C7: ='Income Statement'!I6 -> 38361.6 | E7: ='Income Statement'!I7 -> 23846.966 | F7: ='Income Statement'!I8 -> 14485.115 | H7: Year 4 | I7: ='Income Statement'!I30 -> 16875.33 | K7: Year 4 | L7: ='Income Statement'!I14 -> 37869.901 | O7: Year 4 | P7: ='Income Statement'!I9 -> 76693.681 | R7: Year 4 | S7: ='Balance Sheet'!I28 -> 21200 | U7: Year 4 | V7: ='Balance Sheet'!I20 -> 90843.967
B8: Year 5 | C8: ='Income Statement'!J6 -> 46033.92 | E8: ='Income Statement'!J7 -> 28139.42 | F8: ='Income Statement'!J8 -> 16802.733 | H8: Year 5 | I8: ='Income Statement'!J30 -> 20458.1 | K8: Year 5 | L8: ='Income Statement'!J14 -> 44925.248 | O8: Year 5 | P8: ='Income Statement'!J9 -> 90976.074 | R8: Year 5 | S8: ='Balance Sheet'!J28 -> 20200 | U8: Year 5 | V8: ='Balance Sheet'!J20 -> 111229.89
